Workbook

Sheet Hypothèses communes
A1: Paramètre | B1: Valeur | C1: Unité | D1: Source / méthode
A2: Taux de change | B2: 0.8807 | C2: € par USD | D2: BCE 30/09/2026 : 1 € = 1,1355 USD
A3: TVA France | B3: 0.2 | D3: Taux normal
A4: Shopify Payments % | B4: 0.015 | D4: Cartes UE, https://www.shopify.com/fr/tarifs
A5: Shopify Payments fixe | B5: 0.25 | C5: € / transaction | D5: idem
A6: Assurance fret | B6: 0.005 | C6: % de la valeur | D6: ESTIMATION usage transitaires
A7: Coût d'un retour (port retour) | B7: 5 | C7: € | D7: ESTIMATION étiquette retour Mondial Relay
A8: Perte sur produit retourné | B8: 0.2 | C8: % du coût rendu | D8: ESTIMATION article non revendable neuf
A9: Abonnement Shopify | B9: 36 | C9: € / mois | D9: Shopify Basic mensuel

Sheet Taie soie
A1: Taie d'oreiller 100 % soie de mûrier 25 momme (Chine) — vendue 89 € TTC
A3: HYPOTHÈSES (cases jaunes modifiables) | B3: Valeur | E3: Source / méthode
A4: Prix FOB unitaire (USD) | B4: 15 | E4: Xinlan (Shaoxing) 25 momme 14-15 $ dès 100 pcs ; Zhigeng 15-18 $ (data/fournisseurs_taie.csv)
A5: Quantité commandée (unités) | B5: 200 | E5: 2 coloris × 100 (MOQ Zhigeng 100 / Xinlan 100)
A6: Poids taxable par unité (kg) | B6: 0.3 | E6: ESTIMATION : taie 25 momme ~0,15 kg + boîte cadeau, poids taxable
A7: Fret aérien (€/kg) | B7: 7 | E7: ESTIMATION fret aérien consolidé Chine→CDG 5-8 €/kg, à faire coter (transitaire)
A8: Droit de douane | B8: 0.12 | E8: TARIC 6302 39 90, droit tiers 12 % (consulté 2026-10-02)
A9: Transitaire + dédouanement (€/lot) | B9: 180 | E9: ESTIMATION forfait transitaire + déclaration en douane par lot (devis à obtenir)
A10: Tests / conformité (€/lot) | B10: 250 | E10: ESTIMATION rapport REACH azoïques/CMR par coloris, amorti sur le lot
A11: Packaging de marque (€/unité) | B11: 2.5 | E11: ESTIMATION boîte rigide + papier de soie + carte, 1,5-3 € à 200 pcs
A12: Prix de vente TTC (€) | B12: 89 | E12: Positionnement 25 momme ; cœur DTC FR 55-72 €, luxe 93-125 € (data/p3_taie.md)
A13: Livraison client payée par la marque (€ HT) | B13: 4.5 | E13: Mondial Relay pro ≤1 kg (data/couts_notes.md)
A14: Taux de retour | B14: 0.03 | E14: ESTIMATION : produit literie, retours faibles
A16: COÛT RENDU FRANCE | B16: Total lot (€) | C16: Par unité (€)
A17: Marchandise (FOB × change × quantité) | B17: =$B$4*'Hypothèses communes'!$B$2*$B$5 | C17: =B17/$B$5
A18: Fret aérien | B18: =$B$6*$B$7*$B$5 | C18: =B18/$B$5
A19: Assurance | B19: =(B17+B18)*'Hypothèses communes'!$B$6 | C19: =B19/$B$5
A20: Valeur en douane (CIF) | B20: =B17+B18+B19 | C20: =B20/$B$5
A21: Droits de douane | B21: =B20*$B$8 | C21: =B21/$B$5
A22: Transitaire + dédouanement | B22: =$B$9 | C22: =B22/$B$5
A23: Tests / conformité | B23: =$B$10 | C23: =B23/$B$5
A24: Packaging de marque | B24: =$B$11*$B$5 | C24: =B24/$B$5
A25: COÛT RENDU (hors TVA import, récupérable) | B25: =B20+B21+B22+B23+B24 | C25: =B25/$B$5
A26: TVA import à avancer (récupérée ensuite) | B26: =(B20+B21)*'Hypothèses communes'!$B$3 | C26: =B26/$B$5
A28: UNIT ECONOMICS PAR COMMANDE (1 unité) | B28: €
A29: Prix TTC | B29: =$B$12
A30: Prix HT | B30: =B29/(1+'Hypothèses communes'!$B$3)
A31: Coût rendu unitaire | B31: =C25
A32: Marge brute (€) | B32: =B30-B31
A33: Marge brute % du HT (critère ≥ 65 %) | B33: =B32/B30
A34: Coût rendu % du TTC (critère ≤ 25 %) | B34: =B31/B29
A35: Frais de paiement Shopify | B35: =B29*'Hypothèses communes'!$B$4+'Hypothèses communes'!$B$5
A36: Livraison client | B36: =$B$13
A37: Coût des retours (par commande) | B37: =$B$14*('Hypothèses communes'!$B$7+'Hypothèses communes'!$B$8*B31+B36)
A38: CONTRIBUTION AVANT PUB (€) | B38: =B32-B35-B36-B37
A39: Contribution avant pub % du HT | B39: =B38/B30
A40: CAC SEUIL (point mort par commande, €) | B40: =B38
A41: ROAS seuil (CA TTC / dépense pub) | B41: =B29/B40
A43: SCÉNARIOS DE COÛT D'ACQUISITION | B43: CAC (€) | C43: Contribution après pub (€) | D43: % du HT
A44: Optimiste | B44: 15 | C44: =B38-B44 | D44: =C44/B30 | E44: ESTIMATION : CAC Meta/Google DTC accessoires premium France ; à remplacer par le CAC mesuré au test
...

Sheet Panama
A1: Chapeau Panama toquilla grade 3-4 (Équateur) — vendu 139 € TTC
A3: HYPOTHÈSES (cases jaunes modifiables) | B3: Valeur | E3: Source / méthode
A4: Prix FOB unitaire (USD) | B4: 27.99 | E4: Ecuadorian Crafts grade 3-4 avec logo, MOQ 12 (data/fournisseurs_panama.csv)
A5: Quantité commandée (unités) | B5: 36 | E5: 3 modèles × 12 (MOQ 12)
A6: Poids taxable par unité (kg) | B6: 1 | E6: ESTIMATION poids volumétrique par chapeau en carton gigogne (à coter)
A7: Fret aérien (€/kg) | B7: 8 | E7: ESTIMATION fret aérien Guayaquil/Quito→CDG, à faire coter
A8: Droit de douane | B8: 0 | E8: TARIC 6504 00 00 : droit tiers 0 %, préférence Équateur 0 %
A9: Transitaire + dédouanement (€/lot) | B9: 180 | E9: ESTIMATION forfait transitaire + déclaration
A10: Tests / conformité (€/lot) | B10: 0 | E10: Pas de test chimique obligatoire identifié (paille végétale)
A11: Packaging de marque (€/unité) | B11: 4 | E11: ESTIMATION boîte à chapeau rigide 3-5 €
A12: Prix de vente TTC (€) | B12: 139 | E12: Traclet 65-190 €, MonChapeauPanama 79-139 €, Borsalino 230-270 € (data/p3_panama.md)
A13: Livraison client payée par la marque (€ HT) | B13: 6.5 | E13: ESTIMATION colis volumineux (boîte à chapeau) en point relais/Colissimo
A14: Taux de retour | B14: 0.08 | E14: ESTIMATION : tailles de tour de tête
A16: COÛT RENDU FRANCE | B16: Total lot (€) | C16: Par unité (€)
A17: Marchandise (FOB × change × quantité) | B17: =$B$4*'Hypothèses communes'!$B$2*$B$5 | C17: =B17/$B$5
A18: Fret aérien | B18: =$B$6*$B$7*$B$5 | C18: =B18/$B$5
A19: Assurance | B19: =(B17+B18)*'Hypothèses communes'!$B$6 | C19: =B19/$B$5
A20: Valeur en douane (CIF) | B20: =B17+B18+B19 | C20: =B20/$B$5
A21: Droits de douane | B21: =B20*$B$8 | C21: =B21/$B$5
A22: Transitaire + dédouanement | B22: =$B$9 | C22: =B22/$B$5
A23: Tests / conformité | B23: =$B$10 | C23: =B23/$B$5
A24: Packaging de marque | B24: =$B$11*$B$5 | C24: =B24/$B$5
A25: COÛT RENDU (hors TVA import, récupérable) | B25: =B20+B21+B22+B23+B24 | C25: =B25/$B$5
A26: TVA import à avancer (récupérée ensuite) | B26: =(B20+B21)*'Hypothèses communes'!$B$3 | C26: =B26/$B$5
A28: UNIT ECONOMICS PAR COMMANDE (1 unité) | B28: €
A29: Prix TTC | B29: =$B$12
A30: Prix HT | B30: =B29/(1+'Hypothèses communes'!$B$3)
A31: Coût rendu unitaire | B31: =C25
A32: Marge brute (€) | B32: =B30-B31
A33: Marge brute % du HT (critère ≥ 65 %) | B33: =B32/B30
A34: Coût rendu % du TTC (critère ≤ 25 %) | B34: =B31/B29
A35: Frais de paiement Shopify | B35: =B29*'Hypothèses communes'!$B$4+'Hypothèses communes'!$B$5
A36: Livraison client | B36: =$B$13
A37: Coût des retours (par commande) | B37: =$B$14*('Hypothèses communes'!$B$7+'Hypothèses communes'!$B$8*B31+B36)
A38: CONTRIBUTION AVANT PUB (€) | B38: =B32-B35-B36-B37
A39: Contribution avant pub % du HT | B39: =B38/B30
A40: CAC SEUIL (point mort par commande, €) | B40: =B38
A41: ROAS seuil (CA TTC / dépense pub) | B41: =B29/B40
A43: SCÉNARIOS DE COÛT D'ACQUISITION | B43: CAC (€) | C43: Contribution après pub (€) | D43: % du HT
A44: Optimiste | B44: 20 | C44: =B38-B44 | D44: =C44/B30 | E44: ESTIMATION : CAC Meta/Google DTC accessoires premium France ; à remplacer par le CAC mesuré au test
...

Sheet Kimono
A1: Kimono long coton imprimé au bloc (Jaipur, Inde) — vendu 85 € TTC — PRODUIT RECOMMANDÉ
A3: HYPOTHÈSES (cases jaunes modifiables) | B3: Valeur | E3: Source / méthode
A4: Prix FOB unitaire (USD) | B4: 6.5 | E4: IndiaMART Jaipur ₹450-650 = 5,1-7,4 $ (Meera, Om Shiva, Bhavya) ; Moharis sur devis (data/fournisseurs_kimono.csv)
A5: Quantité commandée (unités) | B5: 120 | E5: 3 motifs × 40 (Moharis MOQ 20/motif)
A6: Poids taxable par unité (kg) | B6: 0.4 | E6: ESTIMATION kimono voile coton ~0,35 kg + emballage
A7: Fret aérien (€/kg) | B7: 6 | E7: ESTIMATION fret aérien Jaipur/Delhi→CDG, à faire coter
A8: Droit de douane | B8: 0.096 | E8: TARIC 6208 91 00 19 : 12 % tiers, SPG Inde 9,6 % (exportateur REX)
A9: Transitaire + dédouanement (€/lot) | B9: 180 | E9: ESTIMATION forfait transitaire + déclaration
A10: Tests / conformité (€/lot) | B10: 200 | E10: ESTIMATION test azoïques EN ISO 14362-1 par lot
A11: Packaging de marque (€/unité) | B11: 1.5 | E11: ESTIMATION pochette coton + étiquette
A12: Prix de vente TTC (€) | B12: 85 | E12: Jamini 75-100 €, Bëllemme 49 €, Cyrillus 25-50 € (data/p3_kimono.md)
A13: Livraison client payée par la marque (€ HT) | B13: 4.5 | E13: Mondial Relay pro ≤1 kg
A14: Taux de retour | B14: 0.08 | E14: ESTIMATION : habillement, coupe ample
A16: COÛT RENDU FRANCE | B16: Total lot (€) | C16: Par unité (€)
A17: Marchandise (FOB × change × quantité) | B17: =$B$4*'Hypothèses communes'!$B$2*$B$5 | C17: =B17/$B$5
A18: Fret aérien | B18: =$B$6*$B$7*$B$5 | C18: =B18/$B$5
A19: Assurance | B19: =(B17+B18)*'Hypothèses communes'!$B$6 | C19: =B19/$B$5
A20: Valeur en douane (CIF) | B20: =B17+B18+B19 | C20: =B20/$B$5
A21: Droits de douane | B21: =B20*$B$8 | C21: =B21/$B$5
A22: Transitaire + dédouanement | B22: =$B$9 | C22: =B22/$B$5
A23: Tests / conformité | B23: =$B$10 | C23: =B23/$B$5
A24: Packaging de marque | B24: =$B$11*$B$5 | C24: =B24/$B$5
A25: COÛT RENDU (hors TVA import, récupérable) | B25: =B20+B21+B22+B23+B24 | C25: =B25/$B$5
A26: TVA import à avancer (récupérée ensuite) | B26: =(B20+B21)*'Hypothèses communes'!$B$3 | C26: =B26/$B$5
A28: UNIT ECONOMICS PAR COMMANDE (1 unité) | B28: €
A29: Prix TTC | B29: =$B$12
A30: Prix HT | B30: =B29/(1+'Hypothèses communes'!$B$3)
A31: Coût rendu unitaire | B31: =C25
A32: Marge brute (€) | B32: =B30-B31
A33: Marge brute % du HT (critère ≥ 65 %) | B33: =B32/B30
A34: Coût rendu % du TTC (critère ≤ 25 %) | B34: =B31/B29
A35: Frais de paiement Shopify | B35: =B29*'Hypothèses communes'!$B$4+'Hypothèses communes'!$B$5
A36: Livraison client | B36: =$B$13
A37: Coût des retours (par commande) | B37: =$B$14*('Hypothèses communes'!$B$7+'Hypothèses communes'!$B$8*B31+B36)
A38: CONTRIBUTION AVANT PUB (€) | B38: =B32-B35-B36-B37
A39: Contribution avant pub % du HT | B39: =B38/B30
A40: CAC SEUIL (point mort par commande, €) | B40: =B38
A41: ROAS seuil (CA TTC / dépense pub) | B41: =B29/B40
A43: SCÉNARIOS DE COÛT D'ACQUISITION | B43: CAC (€) | C43: Contribution après pub (€) | D43: % du HT
A44: Optimiste | B44: 15 | C44: =B38-B44 | D44: =C44/B30 | E44: ESTIMATION : CAC Meta/Google DTC accessoires premium France ; à remplacer par le CAC mesuré au test
...

Sheet Trésorerie kimono
A1: Besoin de trésorerie — lancement kimono (90 jours)
A3: Poste | B3: € | C3: Source / méthode
A4: Stock + import (coût rendu du 1er lot) | B4: ='Kimono'!B25 | C4: Feuille « Kimono »
A5: TVA import avancée (récupérée sous 1-3 mois) | B5: ='Kimono'!B26 | C5: Feuille « Kimono »
A6: Échantillons 5 fournisseurs (~15 $ pièce + DHL Inde) | B6: 200 | C6: ESTIMATION
A7: Test pré-commande (pub + page) | B7: 750 | C7: Budget test 500-1 000 € (rapport §Phase 4)
A8: Création société (micro/SASU) + immatriculation | B8: 300 | C8: ESTIMATION frais annonce légale + greffe
A9: Shopify 3 mois + thème + applis | B9: 250 | C9: 36 €/mois × 3 + thème/app
A10: Marque : nom, logo, dépôt INPI 1 classe | B10: 450 | C10: INPI 190 € (1 classe) + recherche d antériorité 50 € (legalplace.fr/guides/prix-depot-marque-inpi, 2026) + identité visuelle faite par le fondateur ~210 €
A11: Shooting / contenu (fait par le fondateur) | B11: 150 | C11: Accessoires, fonds
A12: Pub de lancement J45-J90 | B12: 2500 | C12: ESTIMATION ~100 commandes × CAC central 25 €
A13: Réassort 2e lot (2 motifs gagnants × 40) | B13: 1100 | C13: ESTIMATION 80 × coût rendu ~13,6 € ; seulement si critères du test atteints
A14: Adhésion Refashion + Triman | B14: 50 | C14: ESTIMATION petite structure
A15: Réserve imprévus (10 %) | B15: =0.1*SUM(B4:B14) | C15: 10 % du total ci-dessus
A16: TOTAL BESOIN DE TRÉSORERIE | B16: =SUM(B4:B15)
